<?xml version="1.0"?>
<robot xmlns:xacro="http://wiki.ros.org/xacro" name="inchworm_static">

    <!-- Note: Only use this URDF when testing the inchworm kinematics. 
    The inchworm will be fixed to a specific position as determined under 'Static Joint to World Frame' comment -->

    <!-- Import Gazebo ROS Control Plugin -->
    <gazebo>
        <plugin name="gazebo_ros_control" filename="libgazebo_ros_control.so">
            <robotNamespace>/inchworm_static</robotNamespace>
        </plugin>
    </gazebo>

    <!-- Joint Properties -->
    <xacro:property name="joint_speed" value="545"/>        <!-- in rpm -->
    <xacro:property name="joint_torque" value="0.03525"/>   <!-- in N-m -->

    <!-- Static Joint to World Frame in Simulation -->
    <link name="world"/>

    <joint name="joint_name" type="fixed">
        <origin xyz="0.0 0.0 0.0" rpy="0.0 0.0 0.0"/>
        <parent link="world"/>
        <!-- Uncomment below if you want to test general kinematics or end effector -->
        <child link="inchworm_main"/>
        <!-- Uncomment below if you want to test front foot kinematics -->
        <!-- <child link="backfoot_ee_link"/>  -->
        <!-- Uncomment below if you want to test back foot kinematics -->
        <!-- <child link="frontfoot_link"/>  -->
    </joint>

    <!-- Links -->
    <link name="inchworm_main">
        <inertial>
            <origin xyz="0.0 0.0 0.0" rpy="0.0 0.0 0.0"/>
            <mass value="0.001"/>
            <inertia ixx="0.0" ixy="0.0" ixz="0.0" iyy="0.0" iyz="0.0" izz="0.0"/>
        </inertial>
    </link>

    <link name="b_link">
        <visual>
            <origin xyz="0 0 0" rpy="0 0 0"/>
            <geometry>
                <mesh filename="package://inchworm_description/meshes/inchworm_blink.dae"/>
            </geometry>
        </visual>
        <inertial>
            <origin xyz="0.0 0.0 0.0" rpy="0.0 0.0 0.0"/>
            <mass value="0.1"/>
            <inertia ixx="0.0" ixy="0.0" ixz="0.0" iyy="0.0" iyz="0.0" izz="0.0"/>
        </inertial>
    </link>
    
    <link name="frontleg_link">
        <visual>
            <origin xyz="0 0 0" rpy="0 0 3.1416"/>
            <geometry>
                <mesh filename="package://inchworm_description/meshes/inchworm_leg.dae"/>
            </geometry>
        </visual>
        <inertial>
            <origin xyz="0.0 0.0 0.0" rpy="0.0 0.0 0.0"/>
            <mass value="0.1"/>
            <inertia ixx="0.0" ixy="0.0" ixz="0.0" iyy="0.0" iyz="0.0" izz="0.0"/>
        </inertial>
    </link>

    <link name="frontfoot_link">
        <visual>
            <origin xyz="0 0 0" rpy="0 0 0"/>
            <geometry>
                <mesh filename="package://inchworm_description/meshes/inchworm_foot.dae"/>
            </geometry>
        </visual>
        <inertial>
            <origin xyz="0.0 0.0 0.0" rpy="0.0 0.0 0.0"/>
            <mass value="0.1"/>
            <inertia ixx="0.0" ixy="0.0" ixz="0.0" iyy="0.0" iyz="0.0" izz="0.0"/>
        </inertial>
    </link>

    <link name="frontfoot_ee_link">
        <inertial>
            <origin xyz="0.0 0.0 0.0" rpy="0.0 0.0 0.0"/>
            <mass value="0.1"/>
            <inertia ixx="0.0" ixy="0.0" ixz="0.0" iyy="0.0" iyz="0.0" izz="0.0"/>
        </inertial>
    </link>

    <link name="c_link">
        <visual>
            <origin xyz="0 0 0" rpy="0 0 0"/>
            <geometry>
                <mesh filename="package://inchworm_description/meshes/inchworm_clink.dae"/>
            </geometry>
        </visual>
        <inertial>
            <origin xyz="0.0 0.0 0.0" rpy="0.0 0.0 0.0"/>
            <mass value="0.1"/>
            <inertia ixx="0.0" ixy="0.0" ixz="0.0" iyy="0.0" iyz="0.0" izz="0.0"/>
        </inertial>
    </link>

    <link name="backleg_link">
        <visual>
            <origin xyz="0 0 0" rpy="0 0 3.1416"/>
            <geometry>
                <mesh filename="package://inchworm_description/meshes/inchworm_leg.dae"/>
            </geometry>
        </visual>
        <inertial>
            <origin xyz="0.0 0.0 0.0" rpy="0.0 0.0 0.0"/>
            <mass value="0.1"/>
            <inertia ixx="0.0" ixy="0.0" ixz="0.0" iyy="0.0" iyz="0.0" izz="0.0"/>
        </inertial>
    </link>

    <link name="backfoot_link">
        <visual>
            <origin xyz="0 0 0" rpy="0 0 0"/>
            <geometry>
                <mesh filename="package://inchworm_description/meshes/inchworm_foot.dae"/>
            </geometry>
        </visual>
        <inertial>
            <origin xyz="0.0 0.0 0.0" rpy="0.0 0.0 0.0"/>
            <mass value="0.1"/>
            <inertia ixx="0.0" ixy="0.0" ixz="0.0" iyy="0.0" iyz="0.0" izz="0.0"/>
        </inertial>
    </link>

    <link name="backfoot_ee_link">
        <inertial>
            <origin xyz="0.0 0.0 0.0" rpy="0.0 0.0 0.0"/>
            <mass value="0.1"/>
            <inertia ixx="0.0" ixy="0.0" ixz="0.0" iyy="0.0" iyz="0.0" izz="0.0"/>
        </inertial>
    </link>

    <!-- Joint Transmission Macro -->
    <xacro:macro name="joint_transmission" params="prefix">
        <transmission name="${prefix}_transmission">
            <type>transmission_interface/SimpleTransmission</type>
            <joint name="${prefix}_joint">
                <hardwareInterface>hardware_interface/PositionJointInterface</hardwareInterface>
            </joint>
            <actuator name="${prefix}_motor"></actuator>
        </transmission>
    </xacro:macro>

    <!-- Joints -->

    <joint name="main_b_joint" type="continuous">
        <origin xyz="0.0 0.0 0.0" rpy="-1.5707 1.5707 0"/>
        <parent link="inchworm_main"/>
        <child link="b_link"/>
        <axis xyz="0 0 1"/>
        <limit  effort="${joint_torque}"
                velocity="${joint_speed * 2 * 3.14159 / 60 }"/>
    </joint>
    <xacro:joint_transmission prefix="main_b"/>

    <joint name="b_frontleg_joint" type="continuous">
        <origin xyz="0.1633 0.0 0.0" rpy="0 0 0"/>
        <parent link="b_link"/>
        <child link="frontleg_link"/>
        <axis xyz="0 0 1"/>
        <limit  effort="${joint_torque}"
                velocity="${joint_speed * 2 * 3.14159 / 60 }"/>
    </joint>
    <xacro:joint_transmission prefix="b_frontleg"/>

    <joint name="frontleg_frontfoot_joint" type="continuous">
        <origin xyz="0.0573 0.0 0.0" rpy="1.5707 0.0 -1.5707"/>
        <parent link="frontleg_link"/>
        <child link="frontfoot_link"/>
        <axis xyz="0 0 1"/>
        <limit  effort="${joint_torque}"
                velocity="${joint_speed * 2 * 3.14159 / 60 }"/>
    </joint>
    <xacro:joint_transmission prefix="frontleg_frontfoot"/>

    <joint name="frontfoot_ee_joint" type="fixed">
        <origin xyz="0.0 0.0 -0.0489" rpy="0.0 0.0 0.0"/>
        <parent link="frontfoot_link"/>
        <child link="frontfoot_ee_link"/>
        <limit  effort="${joint_torque}"
                velocity="${joint_speed * 2 * 3.14159 / 60 }"/>
    </joint>

    <joint name="main_c_joint" type="continuous">
        <origin xyz="0.0 0.0 0.0" rpy="-1.5707 1.5707 0"/>
        <parent link="inchworm_main"/>
        <child link="c_link"/>
        <axis xyz="0 0 1"/>
        <limit  effort="${joint_torque}"
                velocity="${joint_speed * 2 * 3.14159 / 60 }"/>
    </joint>
    <xacro:joint_transmission prefix="main_c"/>

    <joint name="c_backleg_joint" type="continuous">
        <origin xyz="0.1633 0.0 0.0" rpy="0 0 0"/>
        <parent link="c_link"/>
        <child link="backleg_link"/>
        <axis xyz="0 0 1"/>
        <limit  effort="${joint_torque}"
                velocity="${joint_speed * 2 * 3.14159 / 60 }"/>
    </joint>
    <xacro:joint_transmission prefix="c_backleg"/>

    <joint name="backleg_backfoot_joint" type="continuous">
        <origin xyz="0.0573 0.0 0.0" rpy="1.5707 0.0 -1.5707"/>
        <parent link="backleg_link"/>
        <child link="backfoot_link"/>
        <axis xyz="0 0 1"/>
        <limit  effort="${joint_torque}"
                velocity="${joint_speed * 2 * 3.14159 / 60 }"/>
    </joint>
    <xacro:joint_transmission prefix="backleg_backfoot"/>

    <joint name="backfoot_ee_joint" type="fixed">
        <origin xyz="0.0 0.0 -0.0489" rpy="0.0 0.0 0.0"/>
        <parent link="backfoot_link"/>
        <child link="backfoot_ee_link"/>
        <limit  effort="${joint_torque}"
                velocity="${joint_speed * 2 * 3.14159 / 60 }"/>
    </joint>

</robot>