<?xml version="1.0"?>
<robot xmlns:xacro="http://wiki.ros.org/xacro" name="inchworm">

    <!-- Import Gazebo ROS Control Plugin -->
    <gazebo>
        <plugin name="gazebo_ros_control" filename="libgazebo_ros_control.so">
            <robotNamespace>/inchworm</robotNamespace>
        </plugin>
    </gazebo>

    <!-- Links -->
    
    <link name="backfoot_link">
        <visual>
            <origin xyz="0 0 0" rpy="0 0 0"/>
            <geometry>
                <mesh filename="package://maria_inchworm_description/meshes/inchworm_foot.obj"/>
            </geometry>
        </visual>
    </link>
    
    <joint name="back_foot_leg_joint" type="continuous">
        <origin xyz="0.0 0.0 0.0489" rpy="0.0 0.0 0.0"/>
        <parent link="backfoot_link"/>
        <child link="backleg_link"/>
        <axis xyz="0 0 1"/>
    </joint>

    <link name="backleg_link">
        <visual>
            <origin xyz="0 0 0" rpy="0 0 0"/>
            <geometry>
                <mesh filename="package://maria_inchworm_description/meshes/inchworm_leg.obj"/>
            </geometry>
        </visual>
    </link>
    
</robot>